Workbook

Sheet Executive Summary
A1: Deep Materials Engineering Analysis, Standards Verification & Industry Report
A2: Basis: uploaded 'mechanical_materials_properties_tests_master_list.xlsx' (132 grades) + master prompt. Prepared 21 Oct 2026.
A4: 1. Scope and objectives
A5: Scope | B5: Audit and enrich the supplied 132-grade master list: qualified crystal/grain structure, property database, formula register with independent checks, testing-method register, standards audit, error log, industry considerations and application-based selection. Built as a clearly scoped, source-labelled workbook rather than a claim of full completeness.
A7: 2. Key figures (live formulas)
A8: Material grades reviewed (supplied list) | B8: =COUNTA('Master Material Database'!$B$5:$B$136) -> 132
A9: Gap-list grades suggested (not counted) | B9: =COUNTIF('Master Material Database'!$I$5:$I$154,"Not applicable (gap list)") -> 16
A10: Property records (grade/condition rows) | B10: =COUNTA('Material Properties'!$C$5:$C$200) -> 80
A11: Numeric property values recorded | B11: =COUNT('Material Properties'!$F$5:$F$200,'Material Properties'!$H$5:$I$200,'Material Properties'!$K$5:$N$200,'Material Properties'!$P$5:$R$200) -> 508
A12: Grain / crystal-structure family records | B12: =COUNTA('Grain & Crystal Structure'!$B$5:$B$37) -> 33
A13: Formula blocks / independent checks executed | B13: =COUNTIF('Formulas & Worked Examples'!$H$5:$H$400,"Verified")+COUNTIF('Formulas & Worked Examples'!$H$5:$H$400,"Incorrect") -> 19
A14: Testing-method rows | B14: =COUNTA('Testing Methods'!$B$5:$B$200) -> 44
A15: Standards reviewed (14 supplied + supporting) | B15: =COUNTA('Standards Verification'!$B$5:$B$200) -> 27
A16: Errors / corrections logged | B16: =COUNTA('Errors & Corrections'!$B$5:$B$200) -> 22
A17: Industry-consideration entries (advisory) | B17: =COUNTA('Industry Considerations'!$B$5:$B$200) -> 35
A19: 3. Verification status and coverage by domain
A20: Domain | B20: Items reviewed | C20: Verified | D20: Conditionally verified | E20: Incorrect | F20: Unverified | G20: Strict Cv | H20: Conditional Cv | I20: Reconciles?
A21: Master-list designations | B21: =COUNTA('Master Material Database'!$I$5:$I$136) -> 132 | C21: =COUNTIF('Master Material Database'!$I$5:$I$136,"Verified") -> 0 | D21: =COUNTIF('Master Material Database'!$I$5:$I$136,"Conditionally verified") -> 103 | E21: =COUNTIF('Master Material Database'!$I$5:$I$136,"Incorrect") -> 3 | F21: =COUNTIF('Master Material Database'!$I$5:$I$136,"Unverified") -> 26 | G21: =IF(B21>0,C21/B21,0) -> 0 | H21: =IF(B21>0,(C21+D21)/B21,0) -> 0.78030303 | I21: =IF(B21=SUM(C21:F21),"OK","CHECK") -> OK
A22: Property records (Sheet 3) | B22: =COUNTA('Material Properties'!$Z$5:$Z$200) -> 80 | C22: =COUNTIF('Material Properties'!$Z$5:$Z$200,"Verified") -> 0 | D22: =COUNTIF('Material Properties'!$Z$5:$Z$200,"Conditionally verified") -> 54 | E22: =COUNTIF('Material Properties'!$Z$5:$Z$200,"Incorrect") -> 0 | F22: =COUNTIF('Material Properties'!$Z$5:$Z$200,"Unverified") -> 26 | G22: =IF(B22>0,C22/B22,0) -> 0 | H22: =IF(B22>0,(C22+D22)/B22,0) -> 0.675 | I22: =IF(B22=SUM(C22:F22),"OK","CHECK") -> OK
A23: Grain / crystal-structure records | B23: =COUNTA('Grain & Crystal Structure'!$K$5:$K$37) -> 33 | C23: =COUNTIF('Grain & Crystal Structure'!$K$5:$K$37,"Verified") -> 0 | D23: =COUNTIF('Grain & Crystal Structure'!$K$5:$K$37,"Conditionally verified") -> 33 | E23: =COUNTIF('Grain & Crystal Structure'!$K$5:$K$37,"Incorrect") -> 0 | F23: =COUNTIF('Grain & Crystal Structure'!$K$5:$K$37,"Unverified") -> 0 | G23: =IF(B23>0,C23/B23,0) -> 0 | H23: =IF(B23>0,(C23+D23)/B23,0) -> 1 | I23: =IF(B23=SUM(C23:F23),"OK","CHECK") -> OK
A24: Formula checks (Sheet 5) | B24: =SUM(C24:F24) -> 19 | C24: =COUNTIF('Formulas & Worked Examples'!$H$5:$H$400,"Verified") -> 19 | D24: =COUNTIF('Formulas & Worked Examples'!$H$5:$H$400,"Conditionally verified") -> 0 | E24: =COUNTIF('Formulas & Worked Examples'!$H$5:$H$400,"Incorrect") -> 0 | F24: =COUNTIF('Formulas & Worked Examples'!$H$5:$H$400,"Unverified") -> 0 | G24: =IF(B24>0,C24/B24,0) -> 1 | H24: =IF(B24>0,(C24+D24)/B24,0) -> 1 | I24: =IF(B24=SUM(C24:F24),"OK","CHECK") -> OK
A25: Testing-method references | B25: =COUNTA('Testing Methods'!$K$5:$K$200) -> 44 | C25: =COUNTIF('Testing Methods'!$K$5:$K$200,"Verified") -> 0 | D25: =COUNTIF('Testing Methods'!$K$5:$K$200,"Conditionally verified") -> 35 | E25: =COUNTIF('Testing Methods'!$K$5:$K$200,"Incorrect") -> 0 | F25: =COUNTIF('Testing Methods'!$K$5:$K$200,"Unverified") -> 9 | G25: =IF(B25>0,C25/B25,0) -> 0 | H25: =IF(B25>0,(C25+D25)/B25,0) -> 0.79545455 | I25: =IF(B25=SUM(C25:F25),"OK","CHECK") -> OK
A26: Standards (supplied + supporting) | B26: =COUNTA('Standards Verification'!$L$5:$L$200) -> 27 | C26: =COUNTIF('Standards Verification'!$L$5:$L$200,"Verified") -> 0 | D26: =COUNTIF('Standards Verification'!$L$5:$L$200,"Conditionally verified") -> 25 | E26: =COUNTIF('Standards Verification'!$L$5:$L$200,"Incorrect") -> 0 | F26: =COUNTIF('Standards Verification'!$L$5:$L$200,"Unverified") -> 2 | G26: =IF(B26>0,C26/B26,0) -> 0 | H26: =IF(B26>0,(C26+D26)/B26,0) -> 0.92592593 | I26: =IF(B26=SUM(C26:F26),"OK","CHECK") -> OK
A27: TOTAL | B27: =SUM(B21:B26) -> 335 | C27: =SUM(C21:C26) -> 19 | D27: =SUM(D21:D26) -> 250 | E27: =SUM(E21:E26) -> 3 | F27: =SUM(F21:F26) -> 63 | G27: =IF(B27>0,C27/B27,0) -> 0.056716418 | H27: =IF(B27>0,(C27+D27)/B27,0) -> 0.80298507 | I27: =IF(B27=SUM(C27:F27),"OK","CHECK") -> OK
A29: Counting rule | B29: Cv(strict) = N_verified / N_items_reviewed × 100% — 'Verified' means checked against an authoritative document or independently recalculated (all current Verified items are arithmetic/unit checks). Cv(conditional) = (Verified + Conditionally verified) / N_items. Gap-list grades (not in upload) and advisory industry rows are excluded because they are suggestions, not reviewed items. Items are not weighted.
A30: Accuracy vs coverage | B30: Verification coverage is NOT numerical accuracy. Numerical accuracy was not measured (no reference dataset or measurement comparison); property values are recalled handbook/standard values with stated confidence.
A31: Why 90–95% was not reached | B31: No network/authoritative-document access in this session, so standards and datasheet values could not be checked against BIS/ASTM/manufacturer documents. Conditional coverage shows how much is consistent with recalled knowledge; the gap to strict coverage is the remaining verification work (Sheet 11, unresolved items).
A33: 4. Major corrections (details in Sheet 8)
A34: • EN8/EN19/EN24 are withdrawn BS 970 designations — replaced by EN 10083 grades (similar, not identical).
A35: • '/' pairs (1045/C45, 4140/42CrMo4, 52100/100Cr6) are similar, not equivalent.
A36: • 'SS 2xx/3xx' is not a standard designation — use ASTM A240 type/UNS/EN 10088/IS 6911.
A37: • IS 2062 E250/E350 are incomplete without quality designation; 17-4 PH needs ageing condition; 2205 has UNS S32205 and S31803.
A38: • ASTM B117 is an apparatus practice (no pass/fail); ASTM E3 is a Guide; ASTM E164 and IS 1865 status unverified.
A39: • Under-specified items (CoCr, graphite, CBN/PCD, composites, ceramics) cannot carry grade-specific properties.
A41: 5. Important limitations
A42: • Values are recalled typical/specified figures; none re-fetched; no publication dates recorded.
A43: • Standard editions are recalled and may be outdated; paywalled texts were not examined.
A44: • Fatigue, impact and fracture-toughness values are largely not recorded (grade/condition/test-specific).
A45: • Typical values are not guaranteed minimum design properties; use product-standard minima/design allowables.
A46: • Polymers, ceramics, composites are datasheet/grade dependent — ranges are indicative (Low confidence).

Sheet Master Material Database
A1: Sheet 2 — Master Material Database (132 supplied grades + reviewer gap list)
A2: One row per supplied designation. Crystal structure/phase text is qualified by condition — no single structure is assigned to a whole alloy family. Statuses: see Executive Summary definitions.
A4: No. | B4: Designation (as supplied) | C4: Corrected / preferred designation | D4: Material family (supplied) | E4: Candidate governing standards (recalled; verify) | F4: Crystal structure at RT (qualified) | G4: Phases & typical grain / microstructure | H4: Property rows in Sheet 3 [calc] | I4: Designation verification status | J4: Reviewer note
A5: 1 | B5: AISI 1006 | C5: AISI/SAE 1006 (UNS G10060) | D5: Low-carbon steel | E5: ASTM A29/A29M (bar chemistry); A1008/A1011 (sheet); SAE J403 | F5: BCC α-ferrite + orthorhombic Fe3C (cementite) in pearlite | G5: Ferrite-dominant with minor pearlite; equiaxed ferrite grains (hot-rolled/normalised) or elongated (cold-worked). Grain size set by processing — specify per ASTM E112. | H5: =COUNTIF('Material Properties'!$B$5:$B$200,A5) -> 0 | I5: Conditionally verified | J5: Mostly flat-rolled; temper/finish must be stated.
A6: 2 | B6: AISI 1008 | C6: AISI/SAE 1008 (UNS G10080) | D6: Low-carbon steel | E6: ASTM A29/A29M; A1008/A1011; SAE J403 | F6: BCC α-ferrite + orthorhombic Fe3C (cementite) in pearlite | G6: Ferrite-dominant with minor pearlite; equiaxed ferrite grains (hot-rolled/normalised) or elongated (cold-worked). Grain size set by processing — specify per ASTM E112. | H6: =COUNTIF('Material Properties'!$B$5:$B$200,A6) -> 0 | I6: Conditionally verified | J6: Deep-drawing/sheet use.
A7: 3 | B7: AISI 1010 | C7: AISI/SAE 1010 (UNS G10100) | D7: Low-carbon steel | E7: ASTM A29/A29M; A108 (cold-finished) | F7: BCC α-ferrite + orthorhombic Fe3C (cementite) in pearlite | G7: Ferrite-dominant with minor pearlite; equiaxed ferrite grains (hot-rolled/normalised) or elongated (cold-worked). Grain size set by processing — specify per ASTM E112. | H7: =COUNTIF('Material Properties'!$B$5:$B$200,A7) -> 0 | I7: Conditionally verified | J7: Case-hardenable.
A8: 4 | B8: AISI 1018 | C8: AISI/SAE 1018 (UNS G10180) | D8: Low-carbon steel | E8: ASTM A29/A29M; A108 | F8: BCC α-ferrite + orthorhombic Fe3C (cementite) in pearlite | G8: Ferrite-dominant with minor pearlite; equiaxed ferrite grains (hot-rolled/normalised) or elongated (cold-worked). Grain size set by processing — specify per ASTM E112. | H8: =COUNTIF('Material Properties'!$B$5:$B$200,A8) -> 1 | I8: Conditionally verified | J8: Hot-rolled vs cold-drawn properties differ substantially.
A9: 5 | B9: AISI 1020 | C9: AISI/SAE 1020 (UNS G10200) | D9: Low-carbon steel | E9: ASTM A29/A29M; A108 | F9: BCC α-ferrite + orthorhombic Fe3C (cementite) in pearlite | G9: Ferrite-dominant with minor pearlite; equiaxed ferrite grains (hot-rolled/normalised) or elongated (cold-worked). Grain size set by processing — specify per ASTM E112. | H9: =COUNTIF('Material Properties'!$B$5:$B$200,A9) -> 0 | I9: Conditionally verified | J9: Case-hardening response is limited vs alloy steels.
A10: 6 | B10: AISI 1025 | C10: AISI/SAE 1025 (UNS G10250) | D10: Carbon steel | E10: ASTM A29/A29M | F10: BCC α-ferrite + orthorhombic Fe3C (cementite) in pearlite | G10: Ferrite-dominant with minor pearlite; equiaxed ferrite grains (hot-rolled/normalised) or elongated (cold-worked). Grain size set by processing — specify per ASTM E112. | H10: =COUNTIF('Material Properties'!$B$5:$B$200,A10) -> 0 | I10: Conditionally verified
A11: 7 | B11: AISI 1035 | C11: AISI/SAE 1035 (UNS G10350) | D11: Medium-carbon steel | E11: ASTM A29/A29M | F11: BCC α-ferrite + Fe3C (pearlite); BCT martensite if quenched | G11: Ferrite + pearlite (lever-rule estimate ≈44% pearlite at 0.35%C, ≈64% at 0.50%C); tempered martensite after Q&T. Hardenability is carbon-controlled (modest). | H11: =COUNTIF('Material Properties'!$B$5:$B$200,A11) -> 0 | I11: Conditionally verified
A12: 8 | B12: AISI 1040 | C12: AISI/SAE 1040 (UNS G10400) | D12: Medium-carbon steel | E12: ASTM A29/A29M | F12: BCC α-ferrite + Fe3C (pearlite); BCT martensite if quenched | G12: Ferrite + pearlite (lever-rule estimate ≈44% pearlite at 0.35%C, ≈64% at 0.50%C); tempered martensite after Q&T. Hardenability is carbon-controlled (modest). | H12: =COUNTIF('Material Properties'!$B$5:$B$200,A12) -> 0 | I12: Conditionally verified
A13: 9 | B13: AISI 1045 / C45 | C13: AISI/SAE 1045 (UNS G10450). EN C45 (1.0503) is similar, NOT identical | D13: Medium-carbon steel | E13: ASTM A29/A29M; EN 10083-2 (C45) | F13: BCC α-ferrite + Fe3C (pearlite); BCT martensite if quenched | G13: Ferrite + pearlite (lever-rule estimate ≈44% pearlite at 0.35%C, ≈64% at 0.50%C); tempered martensite after Q&T. Hardenability is carbon-controlled (modest). | H13: =COUNTIF('Material Properties'!$B$5:$B$200,A13) -> 1 | I13: Conditionally verified | J13: Slash implies equivalence — see Errors E02.
A14: 10 | B14: AISI 1050 | C14: AISI/SAE 1050 (UNS G10500) | D14: Medium-carbon steel | E14: ASTM A29/A29M | F14: BCC α-ferrite + Fe3C (pearlite); BCT martensite if quenched | G14: Ferrite + pearlite (lever-rule estimate ≈44% pearlite at 0.35%C, ≈64% at 0.50%C); tempered martensite after Q&T. Hardenability is carbon-controlled (modest). | H14: =COUNTIF('Material Properties'!$B$5:$B$200,A14) -> 0 | I14: Conditionally verified
A15: 11 | B15: AISI 1060 | C15: AISI/SAE 1060 (UNS G10600) | D15: High-carbon steel | E15: ASTM A29/A29M | F15: BCC α-ferrite + Fe3C; BCT martensite if quenched | G15: Mostly pearlite (≈77% at 0.60%C by lever rule); fine pearlite/spheroidised or tempered martensite for springs/wear parts. | H15: =COUNTIF('Material Properties'!$B$5:$B$200,A15) -> 0 | I15: Conditionally verified
A16: 12 | B16: IS 2062 E250 | C16: IS 2062:2011 E250 + quality designation (A / BR / B0 / C) | D16: Structural steel | E16: IS 2062 (hot-rolled structural steel); impact/test options depend on quality designation | F16: BCC α-ferrite + orthorhombic Fe3C (cementite) in pearlite | G16: Ferrite-dominant with minor pearlite; equiaxed ferrite grains (hot-rolled/normalised) or elongated (cold-worked). Grain size set by processing — specify per ASTM E112. | H16: =COUNTIF('Material Properties'!$B$5:$B$200,A16) -> 1 | I16: Conditionally verified | J16: Grade without quality designation is incomplete; min. yield falls with thickness (E1).
A17: 13 | B17: IS 2062 E350 | C17: IS 2062:2011 E350 + quality designation | D17: Structural steel | E17: IS 2062 | F17: BCC ferrite + pearlite/bainite; fine Nb/V/Ti carbonitride precipitates | G17: Fine-grained ferrite-pearlite from controlled rolling; strength from grain refinement + precipitation. Weld HAZ grain coarsening can reduce toughness. | H17: =COUNTIF('Material Properties'!$B$5:$B$200,A17) -> 1 | I17: Conditionally verified | J17: As E250; check thickness bands.
A18: 14 | B18: ASTM A36 | C18: ASTM A36/A36M | D18: Structural steel | E18: ASTM A36/A36M | F18: BCC α-ferrite + orthorhombic Fe3C (cementite) in pearlite | G18: Ferrite-dominant with minor pearlite; equiaxed ferrite grains (hot-rolled/normalised) or elongated (cold-worked). Grain size set by processing — specify per ASTM E112. | H18: =COUNTIF('Material Properties'!$B$5:$B$200,A18) -> 1 | I18: Conditionally verified | J18: Plate/shapes/bar; Charpy not required unless ordered.
A19: 15 | B19: ASTM A572 Grade 50 | C19: ASTM A572/A572M Grade 50 | D19: HSLA structural steel | E19: ASTM A572/A572M | F19: BCC ferrite + pearlite/bainite; fine Nb/V/Ti carbonitride precipitates | G19: Fine-grained ferrite-pearlite from controlled rolling; strength from grain refinement + precipitation. Weld HAZ grain coarsening can reduce toughness. | H19: =COUNTIF('Material Properties'!$B$5:$B$200,A19) -> 1 | I19: Conditionally verified | J19: Type (1–5) chemistry should be stated.
A20: 16 | B20: AISI 4130 | C20: AISI/SAE 4130 (UNS G41300) | D20: Cr-Mo alloy steel | E20: ASTM A29/A29M; tubing ASTM A519 | F20: Tempered martensite: BCC ferrite matrix + alloy carbides (as-quenched martensite is BCT) | G20: Q&T gives tempered martensite/bainite; prior-austenite grain size controls toughness. Risks: temper embrittlement, quench cracking, hydrogen embrittlement at high strength. | H20: =COUNTIF('Material Properties'!$B$5:$B$200,A20) -> 1 | I20: Conditionally verified | J20: Weld preheat/PWHT needed for thick sections.
A21: 17 | B21: AISI 4140 / 42CrMo4 | C21: AISI/SAE 4140 (UNS G41400). EN 42CrMo4 (1.7225) is similar, NOT identical | D21: Cr-Mo alloy steel | E21: ASTM A29/A29M; EN 10083-3 (42CrMo4) | F21: Tempered martensite: BCC ferrite matrix + alloy carbides (as-quenched martensite is BCT) | G21: Q&T gives tempered martensite/bainite; prior-austenite grain size controls toughness. Risks: temper embrittlement, quench cracking, hydrogen embrittlement at high strength. | H21: =COUNTIF('Material Properties'!$B$5:$B$200,A21) -> 2 | I21: Conditionally verified | J21: Cr/Mo/Mn/C ranges differ slightly — see Errors E03.
A22: 18 | B22: AISI 4340 | C22: AISI/SAE 4340 (UNS G43400) | D22: Ni-Cr-Mo alloy steel | E22: ASTM A29/A29M | F22: Tempered martensite: BCC ferrite matrix + alloy carbides (as-quenched martensite is BCT) | G22: Q&T gives tempered martensite/bainite; prior-austenite grain size controls toughness. Risks: temper embrittlement, quench cracking, hydrogen embrittlement at high strength. | H22: =COUNTIF('Material Properties'!$B$5:$B$200,A22) -> 1 | I22: Conditionally verified | J22: High hardenability; hydrogen-embrittlement sensitive at high strength.
A23: 19 | B23: AISI 8620 | C23: AISI/SAE 8620 (UNS G86200) | D23: Case-hardening alloy steel | E23: ASTM A29/A29M | F23: Case: high-C tempered martensite (BCT→BCC) + carbides + retained austenite (FCC). Core: low-C martensite/bainite/ferrite | G23: Carburised case (~0.8%C at surface) over a tough low-carbon core; retained austenite, carbide networks and grain-boundary oxidation must be controlled; grinding burn risk. | H23: =COUNTIF('Material Properties'!$B$5:$B$200,A23) -> 1 | I23: Conditionally verified | J23: Gear/shaft case-hardening steel.
A24: 20 | B24: AISI 9310 | C24: AISI/SAE 9310 (UNS G93100) | D24: Case-hardening gear steel | E24: ASTM A29/A29M (aerospace gear grade often per AMS) | F24: Case: high-C tempered martensite (BCT→BCC) + carbides + retained austenite (FCC). Core: low-C martensite/bainite/ferrite | G24: Carburised case (~0.8%C at surface) over a tough low-carbon core; retained austenite, carbide networks and grain-boundary oxidation must be controlled; grinding burn risk. | H24: =COUNTIF('Material Properties'!$B$5:$B$200,A24) -> 0 | I24: Conditionally verified | J24: Heavy-duty/aero gears; vacuum-melt versions exist.
A25: 21 | B25: 16MnCr5 | C25: 16MnCr5 (1.7131) | D25: Case-hardening steel | E25: EN 10084 (case-hardening steels) | F25: Case: high-C tempered martensite (BCT→BCC) + carbides + retained austenite (FCC). Core: low-C martensite/bainite/ferrite | G25: Carburised case (~0.8%C at surface) over a tough low-carbon core; retained austenite, carbide networks and grain-boundary oxidation must be controlled; grinding burn risk. | H25: =COUNTIF('Material Properties'!$B$5:$B$200,A25) -> 0 | I25: Conditionally verified
A26: 22 | B26: 20MnCr5 | C26: 20MnCr5 (1.7147) | D26: Case-hardening steel | E26: EN 10084 | F26: Case: high-C tempered martensite (BCT→BCC) + carbides + retained austenite (FCC). Core: low-C martensite/bainite/ferrite | G26: Carburised case (~0.8%C at surface) over a tough low-carbon core; retained austenite, carbide networks and grain-boundary oxidation must be controlled; grinding burn risk. | H26: =COUNTIF('Material Properties'!$B$5:$B$200,A26) -> 0 | I26: Conditionally verified
A27: 23 | B27: 40Cr | C27: 40Cr (China, GB/T 3077) | D27: Alloy steel | E27: GB/T 3077 (China) | F27: Tempered martensite: BCC ferrite matrix + alloy carbides (as-quenched martensite is BCT) | G27: Q&T gives tempered martensite/bainite; prior-austenite grain size controls toughness. Risks: temper embrittlement, quench cracking, hydrogen embrittlement at high strength. | H27: =COUNTIF('Material Properties'!$B$5:$B$200,A27) -> 0 | I27: Conditionally verified | J27: Chinese designation; no BIS/ASTM equivalence asserted (approx. SAE 5140-type) — Errors E06.
A28: 24 | B28: 20CrMo | C28: 20CrMo (China, GB/T 3077) | D28: Alloy steel | E28: GB/T 3077 (China) | F28: Tempered martensite: BCC ferrite matrix + alloy carbides (as-quenched martensite is BCT) | G28: Q&T gives tempered martensite/bainite; prior-austenite grain size controls toughness. Risks: temper embrittlement, quench cracking, hydrogen embrittlement at high strength. | H28: =COUNTIF('Material Properties'!$B$5:$B$200,A28) -> 0 | I28: Conditionally verified | J28: Chinese designation; carburising/structural; no BIS equivalence asserted.
A29: 25 | B29: 25CrMo4 | C29: 25CrMo4 (1.7218) | D29: Cr-Mo alloy steel | E29: EN 10083-3 | F29: Tempered martensite: BCC ferrite matrix + alloy carbides (as-quenched martensite is BCT) | G29: Q&T gives tempered martensite/bainite; prior-austenite grain size controls toughness. Risks: temper embrittlement, quench cracking, hydrogen embrittlement at high strength. | H29: =COUNTIF('Material Properties'!$B$5:$B$200,A29) -> 0 | I29: Conditionally verified
A30: 26 | B30: 34CrNiMo6 | C30: 34CrNiMo6 (1.6582) | D30: Ni-Cr-Mo alloy steel | E30: EN 10083-3 | F30: Tempered martensite: BCC ferrite matrix + alloy carbides (as-quenched martensite is BCT) | G30: Q&T gives tempered martensite/bainite; prior-austenite grain size controls toughness. Risks: temper embrittlement, quench cracking, hydrogen embrittlement at high strength. | H30: =COUNTIF('Material Properties'!$B$5:$B$200,A30) -> 0 | I30: Conditionally verified | J30: Closest modern grade to legacy EN24 (not identical).
A31: 27 | B31: 18CrNiMo7-6 | C31: 18CrNiMo7-6 (1.6587) | D31: Case-hardening alloy steel | E31: EN 10084 | F31: Case: high-C tempered martensite (BCT→BCC) + carbides + retained austenite (FCC). Core: low-C martensite/bainite/ferrite | G31: Carburised case (~0.8%C at surface) over a tough low-carbon core; retained austenite, carbide networks and grain-boundary oxidation must be controlled; grinding burn risk. | H31: =COUNTIF('Material Properties'!$B$5:$B$200,A31) -> 0 | I31: Conditionally verified | J31: Heavy gears; high core toughness.
A32: 28 | B32: EN8 (verify product standard) | C32: LEGACY: EN8 = BS 970 080M40 (withdrawn). Modern: C40/C45 (EN 10083-2) | D32: Engineering carbon steel | E32: BS 970 withdrawn → BS EN 10083-2 | F32: BCC α-ferrite + Fe3C (pearlite); BCT martensite if quenched | G32: Ferrite + pearlite (lever-rule estimate ≈44% pearlite at 0.35%C, ≈64% at 0.50%C); tempered martensite after Q&T. Hardenability is carbon-controlled (modest). | H32: =COUNTIF('Material Properties'!$B$5:$B$200,A32) -> 0 | I32: Incorrect | J32: Obsolete designation; modern grade similar not identical — Errors E01.
A33: 29 | B33: EN19 (verify product standard) | C33: LEGACY: EN19 = BS 970 709M40/708M40 (withdrawn). Modern: 42CrMo4 | D33: Engineering alloy steel | E33: BS 970 withdrawn → EN 10083-3 | F33: Tempered martensite: BCC ferrite matrix + alloy carbides (as-quenched martensite is BCT) | G33: Q&T gives tempered martensite/bainite; prior-austenite grain size controls toughness. Risks: temper embrittlement, quench cracking, hydrogen embrittlement at high strength. | H33: =COUNTIF('Material Properties'!$B$5:$B$200,A33) -> 0 | I33: Incorrect | J33: Obsolete designation — Errors E01.
A34: 30 | B34: EN24 (verify product standard) | C34: LEGACY: EN24 = BS 970 817M40 (withdrawn). Modern: 34CrNiMo6 (approx.) | D34: Engineering alloy steel | E34: BS 970 withdrawn → EN 10083-3 | F34: Tempered martensite: BCC ferrite matrix + alloy carbides (as-quenched martensite is BCT) | G34: Q&T gives tempered martensite/bainite; prior-austenite grain size controls toughness. Risks: temper embrittlement, quench cracking, hydrogen embrittlement at high strength. | H34: =COUNTIF('Material Properties'!$B$5:$B$200,A34) -> 0 | I34: Incorrect | J34: Obsolete designation — Errors E01.
A35: 31 | B35: SS 201 | C35: ASTM A240 Type 201 (UNS S20100) | D35: Stainless steel | E35: ASTM A240/A240M; IS 6911 (plate/sheet/strip) | F35: FCC γ-austenite | G35: Single-phase austenite with annealing twins; strengthened by cold work (strain-induced martensite possible in 301/304). Sensitisation risk (Cr carbides at grain boundaries) if held ~450–850 °C with higher C. | H35: =COUNTIF('Material Properties'!$B$5:$B$200,A35) -> 0 | I35: Conditionally verified | J35: Mn/N replace part of Ni; lower corrosion resistance; frequently mis-sold as 304 — verify by PMI.
A36: 32 | B36: SS 301 | C36: ASTM A240 Type 301 (UNS S30100) | D36: Austenitic stainless steel | E36: ASTM A240/A240M; A666 (cold-worked tempers) | F36: FCC γ-austenite | G36: Single-phase austenite with annealing twins; strengthened by cold work (strain-induced martensite possible in 301/304). Sensitisation risk (Cr carbides at grain boundaries) if held ~450–850 °C with higher C. | H36: =COUNTIF('Material Properties'!$B$5:$B$200,A36) -> 0 | I36: Conditionally verified | J36: Strain-hardens rapidly; condition (annealed/¼H…) must be stated.
A37: 33 | B37: SS 304 | C37: ASTM A240 Type 304 (UNS S30400) | D37: Austenitic stainless steel | E37: ASTM A240/A240M; IS 6911 | F37: FCC γ-austenite | G37: Single-phase austenite with annealing twins; strengthened by cold work (strain-induced martensite possible in 301/304). Sensitisation risk (Cr carbides at grain boundaries) if held ~450–850 °C with higher C. | H37: =COUNTIF('Material Properties'!$B$5:$B$200,A37) -> 1 | I37: Conditionally verified
A38: 34 | B38: SS 304L | C38: ASTM A240 Type 304L (UNS S30403) | D38: Low-carbon austenitic stainless | E38: ASTM A240/A240M; IS 6911 | F38: FCC γ-austenite | G38: Single-phase austenite with annealing twins; strengthened by cold work (strain-induced martensite possible in 301/304). Sensitisation risk (Cr carbides at grain boundaries) if held ~450–850 °C with higher C. | H38: =COUNTIF('Material Properties'!$B$5:$B$200,A38) -> 0 | I38: Conditionally verified | J38: Low-C for weld sensitisation resistance.
A39: 35 | B39: SS 316 | C39: ASTM A240 Type 316 (UNS S31600) | D39: Austenitic stainless steel | E39: ASTM A240/A240M; IS 6911 | F39: FCC γ-austenite | G39: Single-phase austenite with annealing twins; strengthened by cold work (strain-induced martensite possible in 301/304). Sensitisation risk (Cr carbides at grain boundaries) if held ~450–850 °C with higher C. | H39: =COUNTIF('Material Properties'!$B$5:$B$200,A39) -> 0 | I39: Conditionally verified
A40: 36 | B40: SS 316L | C40: ASTM A240 Type 316L (UNS S31603) | D40: Low-carbon austenitic stainless | E40: ASTM A240/A240M; IS 6911 | F40: FCC γ-austenite | G40: Single-phase austenite with annealing twins; strengthened by cold work (strain-induced martensite possible in 301/304). Sensitisation risk (Cr carbides at grain boundaries) if held ~450–850 °C with higher C. | H40: =COUNTIF('Material Properties'!$B$5:$B$200,A40) -> 1 | I40: Conditionally verified
A41: 37 | B41: SS 321 | C41: ASTM A240 Type 321 (UNS S32100) | D41: Stabilized austenitic stainless | E41: ASTM A240/A240M | F41: FCC γ-austenite | G41: Single-phase austenite with annealing twins; strengthened by cold work (strain-induced martensite possible in 301/304). Sensitisation risk (Cr carbides at grain boundaries) if held ~450–850 °C with higher C. | H41: =COUNTIF('Material Properties'!$B$5:$B$200,A41) -> 0 | I41: Conditionally verified | J41: Ti-stabilised.
...

Sheet Material Properties
A1: Sheet 3 — Material Properties (one row per grade / condition / product form)
A2: Blue = sourced value (recalled, see Sources); grey = Excel formula; no values were invented for blank cells. All RT unless stated.
A4: Prop ID | B4: Master No. | C4: Designation | D4: Condition / product form | E4: Value basis | F4: Density ρ (kg/m³) | G4: Density (g/cm³) [calc] | H4: Young's modulus E (GPa) | I4: Poisson ν | J4: Shear modulus G (GPa) [derived, isotropic] | K4: Yield / proof strength (MPa) | L4: Ultimate tensile strength (MPa) | M4: Flexural strength (MPa) | N4: Elongation at fracture (%) | O4: Hardness (as stated) | P4: Thermal conductivity k (W/(m·K)) | Q4: CTE (µm/(m·K)) | R4: Electrical resistivity (Ω·m) | S4: Strength used [calc] | T4: Specific strength (kN·m/kg) [calc] | U4: Specific stiffness (MN·m/kg) [calc] | V4: Impact / fatigue / KIC / other | W4: Test temperature | X4: Source class | Y4: Confidence | Z4: Verification status | AA4: Limitations / notes
A5: P01 | B5: 4 | C5: AISI 1018 | D5: Cold-drawn bar | E5: Typical | F5: 7870 | G5: =IF(ISNUMBER(F5),F5/1000,"") -> 7.87 | H5: 205 | I5: 0.29 | J5: =IF(AND(ISNUMBER(H5),ISNUMBER(I5)),H5/(2*(1+I5)),"") -> 79.457364 | K5: 370 | L5: 440 | N5: 15 | O5: ≈126 HBW (handbook) | P5: 51.9 | Q5: 11.9 | R5: 1.59e-07 | S5: =IF(ISNUMBER(L5),"UTS",IF(ISNUMBER(K5),"YS",IF(ISNUMBER(M5),"Flexural","—"))) -> UTS | T5: =IF(AND(ISNUMBER(F5),OR(ISNUMBER(L5),ISNUMBER(K5),ISNUMBER(M5))),IF(ISNUMBER(L5),L5,IF(ISNUMBER(K5),K5,M5))*1000/F5,"") -> 55.908513 | U5: =IF(AND(ISNUMBER(F5),ISNUMBER(H5)),H5*1000/F5,"") -> 26.048285 | W5: RT | X5: Handbook typical (ASM/MatWeb-type); recalled, not re-fetched | Y5: Medium | Z5: Conditionally verified | AA5: Hot-rolled condition is lower strength; MatWeb-type values.
A6: P02 | B6: 9 | C6: AISI 1045 | D6: Hot-rolled bar | E6: Typical | F6: 7850 | G6: =IF(ISNUMBER(F6),F6/1000,"") -> 7.85 | H6: 205 | I6: 0.29 | J6: =IF(AND(ISNUMBER(H6),ISNUMBER(I6)),H6/(2*(1+I6)),"") -> 79.457364 | K6: 310 | L6: 565 | N6: 16 | O6: ≈163 HBW | P6: 49.8 | Q6: 11.9 | S6: =IF(ISNUMBER(L6),"UTS",IF(ISNUMBER(K6),"YS",IF(ISNUMBER(M6),"Flexural","—"))) -> UTS | T6: =IF(AND(ISNUMBER(F6),OR(ISNUMBER(L6),ISNUMBER(K6),ISNUMBER(M6))),IF(ISNUMBER(L6),L6,IF(ISNUMBER(K6),K6,M6))*1000/F6,"") -> 71.974522 | U6: =IF(AND(ISNUMBER(F6),ISNUMBER(H6)),H6*1000/F6,"") -> 26.11465 | W6: RT | X6: Handbook typical (ASM/MatWeb-type); recalled, not re-fetched | Y6: Medium | Z6: Conditionally verified | AA6: Cold-drawn and Q&T conditions differ strongly.
A7: P03 | B7: 14 | C7: ASTM A36 | D7: Plate/shapes (specified) | E7: Specified minimum | F7: 7850 | G7: =IF(ISNUMBER(F7),F7/1000,"") -> 7.85 | H7: 200 | I7: 0.3 | J7: =IF(AND(ISNUMBER(H7),ISNUMBER(I7)),H7/(2*(1+I7)),"") -> 76.923077 | K7: 250 | L7: 400 | N7: 20 | O7: n/a | P7: 51.9 | Q7: 11.7 | S7: =IF(ISNUMBER(L7),"UTS",IF(ISNUMBER(K7),"YS",IF(ISNUMBER(M7),"Flexural","—"))) -> UTS | T7: =IF(AND(ISNUMBER(F7),OR(ISNUMBER(L7),ISNUMBER(K7),ISNUMBER(M7))),IF(ISNUMBER(L7),L7,IF(ISNUMBER(K7),K7,M7))*1000/F7,"") -> 50.955414 | U7: =IF(AND(ISNUMBER(F7),ISNUMBER(H7)),H7*1000/F7,"") -> 25.477707 | V7: UTS spec range 400–550; elong. 20% (200 mm GL) / 23% (50 mm GL) | W7: RT | X7: Product-standard value; recalled, standard text not re-read | Y7: Medium | Z7: Conditionally verified | AA7: Minimum values; ρ, E, k, CTE are generic carbon-steel handbook values.
A8: P04 | B8: 12 | C8: IS 2062 E250 | D8: Plate/section ≤20 mm, quality designation A (verify) | E8: Specified minimum | F8: 7850 | G8: =IF(ISNUMBER(F8),F8/1000,"") -> 7.85 | H8: 200 | I8: 0.3 | J8: =IF(AND(ISNUMBER(H8),ISNUMBER(I8)),H8/(2*(1+I8)),"") -> 76.923077 | K8: 250 | L8: 410 | N8: 23 | O8: n/a | S8: =IF(ISNUMBER(L8),"UTS",IF(ISNUMBER(K8),"YS",IF(ISNUMBER(M8),"Flexural","—"))) -> UTS | T8: =IF(AND(ISNUMBER(F8),OR(ISNUMBER(L8),ISNUMBER(K8),ISNUMBER(M8))),IF(ISNUMBER(L8),L8,IF(ISNUMBER(K8),K8,M8))*1000/F8,"") -> 52.229299 | U8: =IF(AND(ISNUMBER(F8),ISNUMBER(H8)),H8*1000/F8,"") -> 25.477707 | W8: RT | X8: Product-standard value; recalled, standard text not re-read | Y8: Medium | Z8: Conditionally verified | AA8: Yield minimum drops with thickness; ρ and E are generic carbon-steel values, not IS 2062-specific.
A9: P05 | B9: 13 | C9: IS 2062 E350 | D9: Plate/section ≤20 mm (verify) | E9: Specified minimum | F9: 7850 | G9: =IF(ISNUMBER(F9),F9/1000,"") -> 7.85 | H9: 200 | I9: 0.3 | J9: =IF(AND(ISNUMBER(H9),ISNUMBER(I9)),H9/(2*(1+I9)),"") -> 76.923077 | K9: 350 | L9: 490 | N9: 22 | O9: n/a | S9: =IF(ISNUMBER(L9),"UTS",IF(ISNUMBER(K9),"YS",IF(ISNUMBER(M9),"Flexural","—"))) -> UTS | T9: =IF(AND(ISNUMBER(F9),OR(ISNUMBER(L9),ISNUMBER(K9),ISNUMBER(M9))),IF(ISNUMBER(L9),L9,IF(ISNUMBER(K9),K9,M9))*1000/F9,"") -> 62.420382 | U9: =IF(AND(ISNUMBER(F9),ISNUMBER(H9)),H9*1000/F9,"") -> 25.477707 | W9: RT | X9: Product-standard value; recalled, standard text not re-read | Y9: Medium | Z9: Conditionally verified | AA9: As E250; confirm thickness bands in standard.
A10: P06 | B10: 15 | C10: ASTM A572 Gr 50 | D10: Plate (specified) | E10: Specified minimum | F10: 7850 | G10: =IF(ISNUMBER(F10),F10/1000,"") -> 7.85 | H10: 200 | I10: 0.3 | J10: =IF(AND(ISNUMBER(H10),ISNUMBER(I10)),H10/(2*(1+I10)),"") -> 76.923077 | K10: 345 | L10: 450 | N10: 18 | O10: n/a | S10: =IF(ISNUMBER(L10),"UTS",IF(ISNUMBER(K10),"YS",IF(ISNUMBER(M10),"Flexural","—"))) -> UTS | T10: =IF(AND(ISNUMBER(F10),OR(ISNUMBER(L10),ISNUMBER(K10),ISNUMBER(M10))),IF(ISNUMBER(L10),L10,IF(ISNUMBER(K10),K10,M10))*1000/F10,"") -> 57.324841 | U10: =IF(AND(ISNUMBER(F10),ISNUMBER(H10)),H10*1000/F10,"") -> 25.477707 | V10: Elong. 18% (200 mm GL) / 21% (50 mm GL) | W10: RT | X10: Product-standard value; recalled, standard text not re-read | Y10: Medium | Z10: Conditionally verified | AA10: Minimum values.
A11: P07 | B11: 16 | C11: AISI 4130 | D11: Normalised 870 °C | E11: Typical | F11: 7850 | G11: =IF(ISNUMBER(F11),F11/1000,"") -> 7.85 | H11: 205 | I11: 0.29 | J11: =IF(AND(ISNUMBER(H11),ISNUMBER(I11)),H11/(2*(1+I11)),"") -> 79.457364 | K11: 435 | L11: 670 | N11: 25.5 | O11: ≈197 HBW | P11: 42.7 | Q11: 12.3 | S11: =IF(ISNUMBER(L11),"UTS",IF(ISNUMBER(K11),"YS",IF(ISNUMBER(M11),"Flexural","—"))) -> UTS | T11: =IF(AND(ISNUMBER(F11),OR(ISNUMBER(L11),ISNUMBER(K11),ISNUMBER(M11))),IF(ISNUMBER(L11),L11,IF(ISNUMBER(K11),K11,M11))*1000/F11,"") -> 85.350318 | U11: =IF(AND(ISNUMBER(F11),ISNUMBER(H11)),H11*1000/F11,"") -> 26.11465 | W11: RT | X11: Handbook typical (ASM/MatWeb-type); recalled, not re-fetched | Y11: Medium | Z11: Conditionally verified | AA11: Strongly condition-dependent (Q&T gives far higher strength).
A12: P08 | B12: 17 | C12: AISI 4140 | D12: Annealed 815 °C, furnace-cooled | E12: Typical | F12: 7850 | G12: =IF(ISNUMBER(F12),F12/1000,"") -> 7.85 | H12: 205 | I12: 0.29 | J12: =IF(AND(ISNUMBER(H12),ISNUMBER(I12)),H12/(2*(1+I12)),"") -> 79.457364 | K12: 417 | L12: 655 | N12: 25.7 | O12: ≈197 HBW | P12: 42.6 | Q12: 12.3 | S12: =IF(ISNUMBER(L12),"UTS",IF(ISNUMBER(K12),"YS",IF(ISNUMBER(M12),"Flexural","—"))) -> UTS | T12: =IF(AND(ISNUMBER(F12),OR(ISNUMBER(L12),ISNUMBER(K12),ISNUMBER(M12))),IF(ISNUMBER(L12),L12,IF(ISNUMBER(K12),K12,M12))*1000/F12,"") -> 83.43949 | U12: =IF(AND(ISNUMBER(F12),ISNUMBER(H12)),H12*1000/F12,"") -> 26.11465 | W12: RT | X12: Handbook typical (ASM/MatWeb-type); recalled, not re-fetched | Y12: Medium | Z12: Conditionally verified
A13: P09 | B13: 17 | C13: AISI 4140 | D13: Q&T (oil quench, ≈650 °C temper) | E13: Typical | F13: 7850 | G13: =IF(ISNUMBER(F13),F13/1000,"") -> 7.85 | H13: 205 | I13: 0.29 | J13: =IF(AND(ISNUMBER(H13),ISNUMBER(I13)),H13/(2*(1+I13)),"") -> 79.457364 | K13: 655 | L13: 758 | N13: 25 | O13: ≈220–235 HBW | P13: 42.6 | Q13: 12.3 | S13: =IF(ISNUMBER(L13),"UTS",IF(ISNUMBER(K13),"YS",IF(ISNUMBER(M13),"Flexural","—"))) -> UTS | T13: =IF(AND(ISNUMBER(F13),OR(ISNUMBER(L13),ISNUMBER(K13),ISNUMBER(M13))),IF(ISNUMBER(L13),L13,IF(ISNUMBER(K13),K13,M13))*1000/F13,"") -> 96.56051 | U13: =IF(AND(ISNUMBER(F13),ISNUMBER(H13)),H13*1000/F13,"") -> 26.11465 | V13: Lower tempering temperature → much higher strength, lower toughness | W13: RT | X13: Handbook typical (ASM/MatWeb-type); recalled, not re-fetched | Y13: Low | Z13: Unverified | AA13: Single tempering point only; use heat-treat curves for design.
A14: P10 | B14: 18 | C14: AISI 4340 | D14: Annealed | E14: Typical | F14: 7850 | G14: =IF(ISNUMBER(F14),F14/1000,"") -> 7.85 | H14: 205 | I14: 0.29 | J14: =IF(AND(ISNUMBER(H14),ISNUMBER(I14)),H14/(2*(1+I14)),"") -> 79.457364 | K14: 472 | L14: 745 | N14: 22 | O14: ≈217 HBW | P14: 44.5 | Q14: 12.3 | S14: =IF(ISNUMBER(L14),"UTS",IF(ISNUMBER(K14),"YS",IF(ISNUMBER(M14),"Flexural","—"))) -> UTS | T14: =IF(AND(ISNUMBER(F14),OR(ISNUMBER(L14),ISNUMBER(K14),ISNUMBER(M14))),IF(ISNUMBER(L14),L14,IF(ISNUMBER(K14),K14,M14))*1000/F14,"") -> 94.904459 | U14: =IF(AND(ISNUMBER(F14),ISNUMBER(H14)),H14*1000/F14,"") -> 26.11465 | W14: RT | X14: Handbook typical (ASM/MatWeb-type); recalled, not re-fetched | Y14: Medium | Z14: Conditionally verified | AA14: Q&T 4340 reaches >1000 MPa UTS — not recorded here.
A15: P11 | B15: 19 | C15: AISI 8620 | D15: Normalised 925 °C (uncarburised core) | E15: Typical | F15: 7850 | G15: =IF(ISNUMBER(F15),F15/1000,"") -> 7.85 | H15: 205 | I15: 0.29 | J15: =IF(AND(ISNUMBER(H15),ISNUMBER(I15)),H15/(2*(1+I15)),"") -> 79.457364 | K15: 357 | L15: 632 | N15: 26 | O15: ≈183 HBW (core) | P15: 46.6 | S15: =IF(ISNUMBER(L15),"UTS",IF(ISNUMBER(K15),"YS",IF(ISNUMBER(M15),"Flexural","—"))) -> UTS | T15: =IF(AND(ISNUMBER(F15),OR(ISNUMBER(L15),ISNUMBER(K15),ISNUMBER(M15))),IF(ISNUMBER(L15),L15,IF(ISNUMBER(K15),K15,M15))*1000/F15,"") -> 80.509554 | U15: =IF(AND(ISNUMBER(F15),ISNUMBER(H15)),H15*1000/F15,"") -> 26.11465 | V15: Carburised case typically ≈58–62 HRC (process result, not base property) | W15: RT | X15: Handbook typical (ASM/MatWeb-type); recalled, not re-fetched | Y15: Medium | Z15: Conditionally verified
A16: P12 | B16: 52 | C16: AISI 52100 | D16: Hardened & tempered (≈150–180 °C) | E16: Typical | F16: 7810 | G16: =IF(ISNUMBER(F16),F16/1000,"") -> 7.81 | H16: 201 | I16: 0.3 | J16: =IF(AND(ISNUMBER(H16),ISNUMBER(I16)),H16/(2*(1+I16)),"") -> 77.307692 | O16: ≈60–66 HRC (bearing practice) | S16: =IF(ISNUMBER(L16),"UTS",IF(ISNUMBER(K16),"YS",IF(ISNUMBER(M16),"Flexural","—"))) -> — | T16: =IF(AND(ISNUMBER(F16),OR(ISNUMBER(L16),ISNUMBER(K16),ISNUMBER(M16))),IF(ISNUMBER(L16),L16,IF(ISNUMBER(K16),K16,M16))*1000/F16,"") | U16: =IF(AND(ISNUMBER(F16),ISNUMBER(H16)),H16*1000/F16,"") -> 25.736236 | V16: Rolling-contact fatigue life depends on cleanliness | W16: RT | X16: Handbook typical (ASM/MatWeb-type); recalled, not re-fetched | Y16: Medium | Z16: Conditionally verified | AA16: Strength not recorded (hardness is the control parameter).
A17: P13 | B17: 33 | C17: SS 304 (A240 Type 304) | D17: Annealed plate/sheet (specified) | E17: Specified minimum | F17: 8000 | G17: =IF(ISNUMBER(F17),F17/1000,"") -> 8 | H17: 193 | I17: 0.29 | J17: =IF(AND(ISNUMBER(H17),ISNUMBER(I17)),H17/(2*(1+I17)),"") -> 74.806202 | K17: 205 | L17: 515 | N17: 40 | O17: ≤201 HBW / ≤92 HRB (A240 max) | P17: 16.2 | Q17: 17.2 | R17: 7.2e-07 | S17: =IF(ISNUMBER(L17),"UTS",IF(ISNUMBER(K17),"YS",IF(ISNUMBER(M17),"Flexural","—"))) -> UTS | T17: =IF(AND(ISNUMBER(F17),OR(ISNUMBER(L17),ISNUMBER(K17),ISNUMBER(M17))),IF(ISNUMBER(L17),L17,IF(ISNUMBER(K17),K17,M17))*1000/F17,"") -> 64.375 | U17: =IF(AND(ISNUMBER(F17),ISNUMBER(H17)),H17*1000/F17,"") -> 24.125 | W17: RT | X17: Product-standard value; recalled, standard text not re-read | Y17: Medium | Z17: Conditionally verified | AA17: k at 100 °C, CTE 0–100 °C. Typical YS ≈215–290 MPa.
A18: P14 | B18: 36 | C18: SS 316L (A240 Type 316L) | D18: Annealed plate/sheet (specified) | E18: Specified minimum | F18: 8000 | G18: =IF(ISNUMBER(F18),F18/1000,"") -> 8 | H18: 193 | I18: 0.3 | J18: =IF(AND(ISNUMBER(H18),ISNUMBER(I18)),H18/(2*(1+I18)),"") -> 74.230769 | K18: 170 | L18: 485 | N18: 40 | O18: ≤217 HBW / ≤95 HRB (A240 max) | P18: 16.3 | Q18: 16 | R18: 7.4e-07 | S18: =IF(ISNUMBER(L18),"UTS",IF(ISNUMBER(K18),"YS",IF(ISNUMBER(M18),"Flexural","—"))) -> UTS | T18: =IF(AND(ISNUMBER(F18),OR(ISNUMBER(L18),ISNUMBER(K18),ISNUMBER(M18))),IF(ISNUMBER(L18),L18,IF(ISNUMBER(K18),K18,M18))*1000/F18,"") -> 60.625 | U18: =IF(AND(ISNUMBER(F18),ISNUMBER(H18)),H18*1000/F18,"") -> 24.125 | W18: RT | X18: Product-standard value; recalled, standard text not re-read | Y18: Medium | Z18: Conditionally verified
A19: P15 | B19: 43 | C19: Duplex 2205 (UNS S32205) | D19: Annealed plate (specified) | E19: Specified minimum | F19: 7800 | G19: =IF(ISNUMBER(F19),F19/1000,"") -> 7.8 | H19: 200 | I19: 0.3 | J19: =IF(AND(ISNUMBER(H19),ISNUMBER(I19)),H19/(2*(1+I19)),"") -> 76.923077 | K19: 450 | L19: 655 | N19: 25 | O19: ≤293 HBW / ≤31 HRC (A240 max) | P19: 19 | Q19: 13 | R19: 8e-07 | S19: =IF(ISNUMBER(L19),"UTS",IF(ISNUMBER(K19),"YS",IF(ISNUMBER(M19),"Flexural","—"))) -> UTS | T19: =IF(AND(ISNUMBER(F19),OR(ISNUMBER(L19),ISNUMBER(K19),ISNUMBER(M19))),IF(ISNUMBER(L19),L19,IF(ISNUMBER(K19),K19,M19))*1000/F19,"") -> 83.974359 | U19: =IF(AND(ISNUMBER(F19),ISNUMBER(H19)),H19*1000/F19,"") -> 25.641026 | W19: RT | X19: Product-standard value; recalled, standard text not re-read | Y19: Medium | Z19: Conditionally verified | AA19: Service temperature typically limited (≈≤250–300 °C) because of 475 °C embrittlement.
A20: P16 | B20: 44 | C20: 17-4 PH (UNS S17400) | D20: Condition H1025 (A564 min) | E20: Specified minimum | F20: 7780 | G20: =IF(ISNUMBER(F20),F20/1000,"") -> 7.78 | H20: 197 | I20: 0.27 | J20: =IF(AND(ISNUMBER(H20),ISNUMBER(I20)),H20/(2*(1+I20)),"") -> 77.559055 | K20: 1000 | L20: 1070 | N20: 12 | O20: ≥35 HRC | S20: =IF(ISNUMBER(L20),"UTS",IF(ISNUMBER(K20),"YS",IF(ISNUMBER(M20),"Flexural","—"))) -> UTS | T20: =IF(AND(ISNUMBER(F20),OR(ISNUMBER(L20),ISNUMBER(K20),ISNUMBER(M20))),IF(ISNUMBER(L20),L20,IF(ISNUMBER(K20),K20,M20))*1000/F20,"") -> 137.53213 | U20: =IF(AND(ISNUMBER(F20),ISNUMBER(H20)),H20*1000/F20,"") -> 25.321337 | W20: RT | X20: Product-standard value; recalled, standard text not re-read | Y20: Medium | Z20: Conditionally verified | AA20: H900 is higher strength/lower toughness; H1150 lower strength/higher toughness.
A21: P17 | B21: 41 | C21: SS 430 (A240 Type 430) | D21: Annealed plate/sheet (specified) | E21: Specified minimum | F21: 7740 | G21: =IF(ISNUMBER(F21),F21/1000,"") -> 7.74 | H21: 200 | I21: 0.28 | J21: =IF(AND(ISNUMBER(H21),ISNUMBER(I21)),H21/(2*(1+I21)),"") -> 78.125 | K21: 205 | L21: 450 | N21: 22 | O21: ≤183 HBW (A240 max) | P21: 26.1 | Q21: 10.4 | R21: 6e-07 | S21: =IF(ISNUMBER(L21),"UTS",IF(ISNUMBER(K21),"YS",IF(ISNUMBER(M21),"Flexural","—"))) -> UTS | T21: =IF(AND(ISNUMBER(F21),OR(ISNUMBER(L21),ISNUMBER(K21),ISNUMBER(M21))),IF(ISNUMBER(L21),L21,IF(ISNUMBER(K21),K21,M21))*1000/F21,"") -> 58.139535 | U21: =IF(AND(ISNUMBER(F21),ISNUMBER(H21)),H21*1000/F21,"") -> 25.839793 | W21: RT | X21: Product-standard value; recalled, standard text not re-read | Y21: Medium | Z21: Conditionally verified
A22: P18 | B22: 42 | C22: SS 440C | D22: Hardened & tempered ≈150–315 °C | E22: Typical | F22: 7650 | G22: =IF(ISNUMBER(F22),F22/1000,"") -> 7.65 | H22: 200 | J22: =IF(AND(ISNUMBER(H22),ISNUMBER(I22)),H22/(2*(1+I22)),"") | O22: ≈57–60 HRC | S22: =IF(ISNUMBER(L22),"UTS",IF(ISNUMBER(K22),"YS",IF(ISNUMBER(M22),"Flexural","—"))) -> — | T22: =IF(AND(ISNUMBER(F22),OR(ISNUMBER(L22),ISNUMBER(K22),ISNUMBER(M22))),IF(ISNUMBER(L22),L22,IF(ISNUMBER(K22),K22,M22))*1000/F22,"") | U22: =IF(AND(ISNUMBER(F22),ISNUMBER(H22)),H22*1000/F22,"") -> 26.143791 | W22: RT | X22: Handbook typical (ASM/MatWeb-type); recalled, not re-fetched | Y22: Medium | Z22: Conditionally verified | AA22: Hardness-only record.
A23: P19 | B23: 47 | C23: AISI D2 | D23: Hardened & tempered (working hardness) | E23: Typical | F23: 7700 | G23: =IF(ISNUMBER(F23),F23/1000,"") -> 7.7 | J23: =IF(AND(ISNUMBER(H23),ISNUMBER(I23)),H23/(2*(1+I23)),"") | O23: ≈58–62 HRC | S23: =IF(ISNUMBER(L23),"UTS",IF(ISNUMBER(K23),"YS",IF(ISNUMBER(M23),"Flexural","—"))) -> — | T23: =IF(AND(ISNUMBER(F23),OR(ISNUMBER(L23),ISNUMBER(K23),ISNUMBER(M23))),IF(ISNUMBER(L23),L23,IF(ISNUMBER(K23),K23,M23))*1000/F23,"") | U23: =IF(AND(ISNUMBER(F23),ISNUMBER(H23)),H23*1000/F23,"") | W23: RT | X23: Handbook typical (ASM/MatWeb-type); recalled, not re-fetched | Y23: Medium | Z23: Conditionally verified | AA23: Hardness depends on tempering temperature.
A24: P20 | B24: 49 | C24: AISI H13 | D24: Hardened & tempered (hot-work practice) | E24: Typical | F24: 7800 | G24: =IF(ISNUMBER(F24),F24/1000,"") -> 7.8 | J24: =IF(AND(ISNUMBER(H24),ISNUMBER(I24)),H24/(2*(1+I24)),"") | O24: ≈44–52 HRC | S24: =IF(ISNUMBER(L24),"UTS",IF(ISNUMBER(K24),"YS",IF(ISNUMBER(M24),"Flexural","—"))) -> — | T24: =IF(AND(ISNUMBER(F24),OR(ISNUMBER(L24),ISNUMBER(K24),ISNUMBER(M24))),IF(ISNUMBER(L24),L24,IF(ISNUMBER(K24),K24,M24))*1000/F24,"") | U24: =IF(AND(ISNUMBER(F24),ISNUMBER(H24)),H24*1000/F24,"") | W24: RT | X24: Handbook typical (ASM/MatWeb-type); recalled, not re-fetched | Y24: Medium | Z24: Conditionally verified
A25: P21 | B25: 50 | C25: AISI M2 | D25: Hardened & tempered | E25: Typical | F25: 8150 | G25: =IF(ISNUMBER(F25),F25/1000,"") -> 8.15 | J25: =IF(AND(ISNUMBER(H25),ISNUMBER(I25)),H25/(2*(1+I25)),"") | O25: ≈62–65 HRC | S25: =IF(ISNUMBER(L25),"UTS",IF(ISNUMBER(K25),"YS",IF(ISNUMBER(M25),"Flexural","—"))) -> — | T25: =IF(AND(ISNUMBER(F25),OR(ISNUMBER(L25),ISNUMBER(K25),ISNUMBER(M25))),IF(ISNUMBER(L25),L25,IF(ISNUMBER(K25),K25,M25))*1000/F25,"") | U25: =IF(AND(ISNUMBER(F25),ISNUMBER(H25)),H25*1000/F25,"") | W25: RT | X25: Handbook typical (ASM/MatWeb-type); recalled, not re-fetched | Y25: Medium | Z25: Conditionally verified
A26: P22 | B26: 45 | C26: AISI O1 | D26: Hardened & tempered | E26: Typical | F26: 7810 | G26: =IF(ISNUMBER(F26),F26/1000,"") -> 7.81 | J26: =IF(AND(ISNUMBER(H26),ISNUMBER(I26)),H26/(2*(1+I26)),"") | O26: ≈57–62 HRC | S26: =IF(ISNUMBER(L26),"UTS",IF(ISNUMBER(K26),"YS",IF(ISNUMBER(M26),"Flexural","—"))) -> — | T26: =IF(AND(ISNUMBER(F26),OR(ISNUMBER(L26),ISNUMBER(K26),ISNUMBER(M26))),IF(ISNUMBER(L26),L26,IF(ISNUMBER(K26),K26,M26))*1000/F26,"") | U26: =IF(AND(ISNUMBER(F26),ISNUMBER(H26)),H26*1000/F26,"") | W26: RT | X26: Handbook typical (ASM/MatWeb-type); recalled, not re-fetched | Y26: Medium | Z26: Conditionally verified
A27: P23 | B27: 46 | C27: AISI A2 | D27: Hardened & tempered | E27: Typical | F27: 7860 | G27: =IF(ISNUMBER(F27),F27/1000,"") -> 7.86 | J27: =IF(AND(ISNUMBER(H27),ISNUMBER(I27)),H27/(2*(1+I27)),"") | O27: ≈57–62 HRC | S27: =IF(ISNUMBER(L27),"UTS",IF(ISNUMBER(K27),"YS",IF(ISNUMBER(M27),"Flexural","—"))) -> — | T27: =IF(AND(ISNUMBER(F27),OR(ISNUMBER(L27),ISNUMBER(K27),ISNUMBER(M27))),IF(ISNUMBER(L27),L27,IF(ISNUMBER(K27),K27,M27))*1000/F27,"") | U27: =IF(AND(ISNUMBER(F27),ISNUMBER(H27)),H27*1000/F27,"") | W27: RT | X27: Handbook typical (ASM/MatWeb-type); recalled, not re-fetched | Y27: Medium | Z27: Conditionally verified
A28: P24 | B28: 56 | C28: IS 210 FG 150 | D28: Separately cast test bar (specified) | E28: Specified minimum | F28: 7100 | G28: =IF(ISNUMBER(F28),F28/1000,"") -> 7.1 | H28: 85 | I28: 0.26 | J28: =IF(AND(ISNUMBER(H28),ISNUMBER(I28)),H28/(2*(1+I28)),"") -> 33.730159 | L28: 150 | O28: casting-section dependent | S28: =IF(ISNUMBER(L28),"UTS",IF(ISNUMBER(K28),"YS",IF(ISNUMBER(M28),"Flexural","—"))) -> UTS | T28: =IF(AND(ISNUMBER(F28),OR(ISNUMBER(L28),ISNUMBER(K28),ISNUMBER(M28))),IF(ISNUMBER(L28),L28,IF(ISNUMBER(K28),K28,M28))*1000/F28,"") -> 21.126761 | U28: =IF(AND(ISNUMBER(F28),ISNUMBER(H28)),H28*1000/F28,"") -> 11.971831 | V28: No distinct yield; brittle (<1% elong.); compressive strength ≈3–4× tensile | W28: RT | X28: Product-standard value; recalled, standard text not re-read | Y28: Low | Z28: Unverified | AA28: ρ, E approximate class-range midpoints; E depends on stress level.
A29: P25 | B29: 57 | C29: IS 210 FG 200 | D29: Separately cast test bar (specified) | E29: Specified minimum | F29: 7100 | G29: =IF(ISNUMBER(F29),F29/1000,"") -> 7.1 | H29: 100 | I29: 0.26 | J29: =IF(AND(ISNUMBER(H29),ISNUMBER(I29)),H29/(2*(1+I29)),"") -> 39.68254 | L29: 200 | O29: ≈150–220 HBW (typical) | S29: =IF(ISNUMBER(L29),"UTS",IF(ISNUMBER(K29),"YS",IF(ISNUMBER(M29),"Flexural","—"))) -> UTS | T29: =IF(AND(ISNUMBER(F29),OR(ISNUMBER(L29),ISNUMBER(K29),ISNUMBER(M29))),IF(ISNUMBER(L29),L29,IF(ISNUMBER(K29),K29,M29))*1000/F29,"") -> 28.169014 | U29: =IF(AND(ISNUMBER(F29),ISNUMBER(H29)),H29*1000/F29,"") -> 14.084507 | V29: Damping high vs steel | W29: RT | X29: Product-standard value; recalled, standard text not re-read | Y29: Low | Z29: Unverified | AA29: As FG 150.
A30: P26 | B30: 58 | C30: IS 210 FG 260 | D30: Separately cast test bar (specified) | E30: Specified minimum | F30: 7100 | G30: =IF(ISNUMBER(F30),F30/1000,"") -> 7.1 | H30: 115 | I30: 0.26 | J30: =IF(AND(ISNUMBER(H30),ISNUMBER(I30)),H30/(2*(1+I30)),"") -> 45.634921 | L30: 260 | O30: casting-section dependent | S30: =IF(ISNUMBER(L30),"UTS",IF(ISNUMBER(K30),"YS",IF(ISNUMBER(M30),"Flexural","—"))) -> UTS | T30: =IF(AND(ISNUMBER(F30),OR(ISNUMBER(L30),ISNUMBER(K30),ISNUMBER(M30))),IF(ISNUMBER(L30),L30,IF(ISNUMBER(K30),K30,M30))*1000/F30,"") -> 36.619718 | U30: =IF(AND(ISNUMBER(F30),ISNUMBER(H30)),H30*1000/F30,"") -> 16.197183 | W30: RT | X30: Product-standard value; recalled, standard text not re-read | Y30: Low | Z30: Unverified | AA30: As FG 150.
A31: P27 | B31: 59 | C31: EN-GJL-200 | D31: Separately cast bar (specified min) | E31: Specified minimum | F31: 7100 | G31: =IF(ISNUMBER(F31),F31/1000,"") -> 7.1 | H31: 100 | I31: 0.26 | J31: =IF(AND(ISNUMBER(H31),ISNUMBER(I31)),H31/(2*(1+I31)),"") -> 39.68254 | L31: 200 | O31: informative only | S31: =IF(ISNUMBER(L31),"UTS",IF(ISNUMBER(K31),"YS",IF(ISNUMBER(M31),"Flexural","—"))) -> UTS | T31: =IF(AND(ISNUMBER(F31),OR(ISNUMBER(L31),ISNUMBER(K31),ISNUMBER(M31))),IF(ISNUMBER(L31),L31,IF(ISNUMBER(K31),K31,M31))*1000/F31,"") -> 28.169014 | U31: =IF(AND(ISNUMBER(F31),ISNUMBER(H31)),H31*1000/F31,"") -> 14.084507 | W31: RT | X31: Product-standard value; recalled, standard text not re-read | Y31: Low | Z31: Unverified | AA31: EN 1561 gives Rm range; E approximate.
A32: P28 | B32: 60 | C32: EN-GJL-250 | D32: Separately cast bar (specified min) | E32: Specified minimum | F32: 7100 | G32: =IF(ISNUMBER(F32),F32/1000,"") -> 7.1 | H32: 115 | I32: 0.26 | J32: =IF(AND(ISNUMBER(H32),ISNUMBER(I32)),H32/(2*(1+I32)),"") -> 45.634921 | L32: 250 | O32: informative only | S32: =IF(ISNUMBER(L32),"UTS",IF(ISNUMBER(K32),"YS",IF(ISNUMBER(M32),"Flexural","—"))) -> UTS | T32: =IF(AND(ISNUMBER(F32),OR(ISNUMBER(L32),ISNUMBER(K32),ISNUMBER(M32))),IF(ISNUMBER(L32),L32,IF(ISNUMBER(K32),K32,M32))*1000/F32,"") -> 35.211268 | U32: =IF(AND(ISNUMBER(F32),ISNUMBER(H32)),H32*1000/F32,"") -> 16.197183 | W32: RT | X32: Product-standard value; recalled, standard text not re-read | Y32: Low | Z32: Unverified
A33: P29 | B33: 64 | C33: ASTM A48 Class 30 | D33: Separately cast bar (specified) | E33: Specified minimum | F33: 7100 | G33: =IF(ISNUMBER(F33),F33/1000,"") -> 7.1 | H33: 100 | I33: 0.26 | J33: =IF(AND(ISNUMBER(H33),ISNUMBER(I33)),H33/(2*(1+I33)),"") -> 39.68254 | L33: 207 | O33: n/a | S33: =IF(ISNUMBER(L33),"UTS",IF(ISNUMBER(K33),"YS",IF(ISNUMBER(M33),"Flexural","—"))) -> UTS | T33: =IF(AND(ISNUMBER(F33),OR(ISNUMBER(L33),ISNUMBER(K33),ISNUMBER(M33))),IF(ISNUMBER(L33),L33,IF(ISNUMBER(K33),K33,M33))*1000/F33,"") -> 29.15493 | U33: =IF(AND(ISNUMBER(F33),ISNUMBER(H33)),H33*1000/F33,"") -> 14.084507 | V33: 30 ksi min tensile | W33: RT | X33: Product-standard value; recalled, standard text not re-read | Y33: Low | Z33: Unverified | AA33: E approximate class-range midpoint.
A34: P30 | B34: 61 | C34: EN-GJS-400-15 | D34: Separately cast bar (specified min) | E34: Specified minimum | F34: 7100 | G34: =IF(ISNUMBER(F34),F34/1000,"") -> 7.1 | H34: 169 | I34: 0.275 | J34: =IF(AND(ISNUMBER(H34),ISNUMBER(I34)),H34/(2*(1+I34)),"") -> 66.27451 | K34: 250 | L34: 400 | N34: 15 | O34: ≈135–180 HBW (informative) | S34: =IF(ISNUMBER(L34),"UTS",IF(ISNUMBER(K34),"YS",IF(ISNUMBER(M34),"Flexural","—"))) -> UTS | T34: =IF(AND(ISNUMBER(F34),OR(ISNUMBER(L34),ISNUMBER(K34),ISNUMBER(M34))),IF(ISNUMBER(L34),L34,IF(ISNUMBER(K34),K34,M34))*1000/F34,"") -> 56.338028 | U34: =IF(AND(ISNUMBER(F34),ISNUMBER(H34)),H34*1000/F34,"") -> 23.802817 | W34: RT | X34: Product-standard value; recalled, standard text not re-read | Y34: Medium | Z34: Conditionally verified | AA34: Rp0.2 / Rm / A minima.
A35: P31 | B35: 62 | C35: EN-GJS-500-7 | D35: Separately cast bar (specified min) | E35: Specified minimum | F35: 7100 | G35: =IF(ISNUMBER(F35),F35/1000,"") -> 7.1 | H35: 169 | I35: 0.275 | J35: =IF(AND(ISNUMBER(H35),ISNUMBER(I35)),H35/(2*(1+I35)),"") -> 66.27451 | K35: 320 | L35: 500 | N35: 7 | O35: ≈170–230 HBW (informative) | S35: =IF(ISNUMBER(L35),"UTS",IF(ISNUMBER(K35),"YS",IF(ISNUMBER(M35),"Flexural","—"))) -> UTS | T35: =IF(AND(ISNUMBER(F35),OR(ISNUMBER(L35),ISNUMBER(K35),ISNUMBER(M35))),IF(ISNUMBER(L35),L35,IF(ISNUMBER(K35),K35,M35))*1000/F35,"") -> 70.422535 | U35: =IF(AND(ISNUMBER(F35),ISNUMBER(H35)),H35*1000/F35,"") -> 23.802817 | W35: RT | X35: Product-standard value; recalled, standard text not re-read | Y35: Medium | Z35: Conditionally verified
A36: P32 | B36: 63 | C36: ASTM A536 65-45-12 | D36: Specified | E36: Specified minimum | F36: 7100 | G36: =IF(ISNUMBER(F36),F36/1000,"") -> 7.1 | H36: 169 | I36: 0.275 | J36: =IF(AND(ISNUMBER(H36),ISNUMBER(I36)),H36/(2*(1+I36)),"") -> 66.27451 | K36: 310 | L36: 448 | N36: 12 | O36: typ. ≈156–217 HBW | S36: =IF(ISNUMBER(L36),"UTS",IF(ISNUMBER(K36),"YS",IF(ISNUMBER(M36),"Flexural","—"))) -> UTS | T36: =IF(AND(ISNUMBER(F36),OR(ISNUMBER(L36),ISNUMBER(K36),ISNUMBER(M36))),IF(ISNUMBER(L36),L36,IF(ISNUMBER(K36),K36,M36))*1000/F36,"") -> 63.098592 | U36: =IF(AND(ISNUMBER(F36),ISNUMBER(H36)),H36*1000/F36,"") -> 23.802817 | V36: 65/45 ksi | W36: RT | X36: Product-standard value; recalled, standard text not re-read | Y36: Medium | Z36: Conditionally verified
A37: P33 | B37: 72 | C37: AA 6061-T6 | D37: Sheet/plate/extrusion (typical) | E37: Typical | F37: 2700 | G37: =IF(ISNUMBER(F37),F37/1000,"") -> 2.7 | H37: 68.9 | I37: 0.33 | J37: =IF(AND(ISNUMBER(H37),ISNUMBER(I37)),H37/(2*(1+I37)),"") -> 25.902256 | K37: 276 | L37: 310 | N37: 12 | O37: ≈95 HBW | P37: 167 | Q37: 23.6 | R37: 3.99e-08 | S37: =IF(ISNUMBER(L37),"UTS",IF(ISNUMBER(K37),"YS",IF(ISNUMBER(M37),"Flexural","—"))) -> UTS | T37: =IF(AND(ISNUMBER(F37),OR(ISNUMBER(L37),ISNUMBER(K37),ISNUMBER(M37))),IF(ISNUMBER(L37),L37,IF(ISNUMBER(K37),K37,M37))*1000/F37,"") -> 114.81481 | U37: =IF(AND(ISNUMBER(F37),ISNUMBER(H37)),H37*1000/F37,"") -> 25.518519 | V37: Fatigue ≈96.5 MPa at 5×10^8 cycles (R. R. Moore, R=−1) | W37: RT | X37: Handbook typical (ASM/MatWeb-type); recalled, not re-fetched | Y37: Medium | Z37: Conditionally verified | AA37: ASTM minima are lower (e.g. ≈240/260 MPa for some extrusions).
A38: P34 | B38: 76 | C38: AA 7075-T6 | D38: Sheet/plate (typical) | E38: Typical | F38: 2810 | G38: =IF(ISNUMBER(F38),F38/1000,"") -> 2.81 | H38: 71.7 | I38: 0.33 | J38: =IF(AND(ISNUMBER(H38),ISNUMBER(I38)),H38/(2*(1+I38)),"") -> 26.954887 | K38: 503 | L38: 572 | N38: 11 | O38: ≈150 HBW | P38: 130 | Q38: 23.4 | R38: 5.15e-08 | S38: =IF(ISNUMBER(L38),"UTS",IF(ISNUMBER(K38),"YS",IF(ISNUMBER(M38),"Flexural","—"))) -> UTS | T38: =IF(AND(ISNUMBER(F38),OR(ISNUMBER(L38),ISNUMBER(K38),ISNUMBER(M38))),IF(ISNUMBER(L38),L38,IF(ISNUMBER(K38),K38,M38))*1000/F38,"") -> 203.55872 | U38: =IF(AND(ISNUMBER(F38),ISNUMBER(H38)),H38*1000/F38,"") -> 25.516014 | V38: Fatigue ≈159 MPa at 5×10^8 cycles; KIC ≈29 MPa√m (T651, L-T, approx.) | W38: RT | X38: Handbook typical (ASM/MatWeb-type); recalled, not re-fetched | Y38: Medium | Z38: Conditionally verified | AA38: SCC-susceptible short-transverse.
A39: P35 | B39: 68 | C39: AA 2024-T3 | D39: Sheet (typical) | E39: Typical | F39: 2780 | G39: =IF(ISNUMBER(F39),F39/1000,"") -> 2.78 | H39: 73.1 | I39: 0.33 | J39: =IF(AND(ISNUMBER(H39),ISNUMBER(I39)),H39/(2*(1+I39)),"") -> 27.481203 | K39: 345 | L39: 483 | N39: 18 | O39: ≈120 HBW | P39: 121 | Q39: 23.2 | R39: 5.82e-08 | S39: =IF(ISNUMBER(L39),"UTS",IF(ISNUMBER(K39),"YS",IF(ISNUMBER(M39),"Flexural","—"))) -> UTS | T39: =IF(AND(ISNUMBER(F39),OR(ISNUMBER(L39),ISNUMBER(K39),ISNUMBER(M39))),IF(ISNUMBER(L39),L39,IF(ISNUMBER(K39),K39,M39))*1000/F39,"") -> 173.74101 | U39: =IF(AND(ISNUMBER(F39),ISNUMBER(H39)),H39*1000/F39,"") -> 26.294964 | V39: Fatigue ≈138 MPa at 5×10^8 cycles | W39: RT | X39: Handbook typical (ASM/MatWeb-type); recalled, not re-fetched | Y39: Medium | Z39: Conditionally verified
A40: P36 | B40: 67 | C40: AA 2014-T6 | D40: Bar/forging (typical) | E40: Typical | F40: 2800 | G40: =IF(ISNUMBER(F40),F40/1000,"") -> 2.8 | H40: 72.4 | I40: 0.33 | J40: =IF(AND(ISNUMBER(H40),ISNUMBER(I40)),H40/(2*(1+I40)),"") -> 27.218045 | K40: 414 | L40: 483 | N40: 13 | O40: ≈135 HBW | P40: 154 | Q40: 23 | S40: =IF(ISNUMBER(L40),"UTS",IF(ISNUMBER(K40),"YS",IF(ISNUMBER(M40),"Flexural","—"))) -> UTS | T40: =IF(AND(ISNUMBER(F40),OR(ISNUMBER(L40),ISNUMBER(K40),ISNUMBER(M40))),IF(ISNUMBER(L40),L40,IF(ISNUMBER(K40),K40,M40))*1000/F40,"") -> 172.5 | U40: =IF(AND(ISNUMBER(F40),ISNUMBER(H40)),H40*1000/F40,"") -> 25.857143 | W40: RT | X40: Handbook typical (ASM/MatWeb-type); recalled, not re-fetched | Y40: Medium | Z40: Conditionally verified
A41: P37 | B41: 70 | C41: AA 5052-H32 | D41: Sheet (typical) | E41: Typical | F41: 2680 | G41: =IF(ISNUMBER(F41),F41/1000,"") -> 2.68 | H41: 70.3 | I41: 0.33 | J41: =IF(AND(ISNUMBER(H41),ISNUMBER(I41)),H41/(2*(1+I41)),"") -> 26.428571 | K41: 193 | L41: 228 | N41: 12 | O41: ≈60 HBW | P41: 138 | Q41: 23.8 | R41: 4.95e-08 | S41: =IF(ISNUMBER(L41),"UTS",IF(ISNUMBER(K41),"YS",IF(ISNUMBER(M41),"Flexural","—"))) -> UTS | T41: =IF(AND(ISNUMBER(F41),OR(ISNUMBER(L41),ISNUMBER(K41),ISNUMBER(M41))),IF(ISNUMBER(L41),L41,IF(ISNUMBER(K41),K41,M41))*1000/F41,"") -> 85.074627 | U41: =IF(AND(ISNUMBER(F41),ISNUMBER(H41)),H41*1000/F41,"") -> 26.231343 | V41: Fatigue ≈117 MPa at 5×10^8 cycles | W41: RT | X41: Handbook typical (ASM/MatWeb-type); recalled, not re-fetched | Y41: Medium | Z41: Conditionally verified
...

Sheet Grain & Crystal Structure
A1: Sheet 4 — Grain, Crystal & Microstructure Reference (family level)
A2: Numbers in [ ] are Master No. from the upload. Grain size and phases depend on processing; no family-wide single value is implied. Statements are textbook-level knowledge, not re-checked against sources.
A4: ID | B4: Family / group | C4: Representative grades [Master No.] | D4: Crystal structure at RT | E4: Phases / constituents | F4: Typical grain / microstructure | G4: Strengthening mechanisms | H4: Heat-treatment / processing response | I4: Structure → property effects & key risks | J4: Metallography / grain-size method | K4: Verification status
A5: GS01 | B5: Low-carbon / structural steels | C5: 1006–1025, A36, IS 2062 E250 [1–6,12,14] | D5: BCC α-ferrite (+ orthorhombic Fe3C) | E5: Ferrite + pearlite | F5: Equiaxed ferrite (hot-rolled/normalised); elongated + dislocation-dense (cold-drawn) | G5: Grain-boundary (Hall–Petch), solid solution (Mn, Si), work hardening | H5: Normalise to refine grain; cold work raises strength; limited hardenability | I5: Fine grain → higher yield and lower ductile-brittle transition temperature (BCC DBTT); banding and decarburisation are quality risks | J5: ASTM E112 grain size; E3/E407 prep/etch; E45 inclusions | K5: Conditionally verified
A6: GS02 | B6: Medium/high-carbon steels | C6: 1035–1060, 65Mn [7–11,55] | D6: BCC α-ferrite + Fe3C; BCT martensite when quenched | E6: Pearlite fraction rises with C | F6: Pearlite colonies/lamellar spacing; spheroidised for machinability | G6: Pearlite spacing, martensite (carbon), tempering carbides | H6: Q&T; induction hardening; as-quenched BCT c/a ≈1+0.045·%C (approx.) | I6: Fine pearlite = strength; coarse = ductility; quench cracking above ≈0.4–0.5%C in water | J6: E112; hardness traverse; E3 | K6: Conditionally verified
A7: GS03 | B7: HSLA structural steels | C7: E350, A572 Gr50 [13,15] | D7: BCC ferrite + pearlite/bainite | E7: Nb/V/Ti carbonitrides | F7: Very fine ferrite from controlled rolling (TMCP) | G7: Grain refinement, precipitation, solid solution | H7: Controlled rolling/accelerated cooling; no Q&T | I7: HAZ grain coarsening/ MA constituents reduce toughness; weld procedure & CE control | J7: E112; Charpy per grade | K7: Conditionally verified
